<?xml version="1.0"?>
<robot xmlns:xacro="http://www.ros.org/wiki/xacro" name="myrobot"> 
  
  <xacro:include filename="$(find description_pkg)/urdf/material.xacro"/>

  <link name="base_link">
  </link>
  
   <joint name="joint_base" type="fixed">
        <parent link="base_link"/>
        <child link="chassis"/>
        <origin xyz="0.0 0.0 0.00" rpy="0.0 0.0 0.0"/>
  </joint>


  <!--________________ CHASSIS LINK________________ -->
  <link name="chassis">
        <inertial>
            <origin xyz="0.0 0.0 0.0"/>
            <mass value="20"/>
            <inertia ixx="0.1" ixy="0.0" ixz="0.0" iyy="0.1" iyz="0.0" izz="0.1"/>
        </inertial>
        <visual name='1'>
            <origin xyz="0.0 0.0 0.20" />
            <geometry>
                <box size="0.6 0.45 0.1"/>
            </geometry>
            <material name="white"/>
        </visual>
        <collision name='1'>
            <origin xyz="0.0 0.0 0.2" rpy="0.0 0.0 0.0"/>
            <geometry>
                <box size="0.6 0.45 0.1"/>
            </geometry>
        </collision>
        <visual name='2'>
            <origin xyz="-0.10 0.0 0.30" />
            <geometry>
                <box size="0.4 0.45 0.1"/>
            </geometry>
            <material name="white"/>
        </visual>
        <collision name='2'>
            <origin xyz="-0.10 0.0 0.30" />
            <geometry>
                <box size="0.4 0.45 0.1"/>
            </geometry>
        </collision>    
      <collision name="back_right_wheel_collision">
        <origin rpy="0 1.5707 1.5707" xyz="-0.175 -0.25 0.1" />
        <geometry>
          <cylinder length="0.05" radius="0.1"/>
        </geometry>
      </collision>
      
      <visual name="back_right_wheel_visual">
        <origin rpy="0 1.5707 1.5707" xyz="-0.175 -0.25 0.1"/>
        <geometry>
          <cylinder length="0.05" radius="0.1"/>
        </geometry>  
        <material name="Black"/>    
      </visual> 

          <collision name="back_left_wheel_collision">
        <origin rpy="0 1.5707 1.5707" xyz="-0.175 0.25 0.1" />
        <geometry>
          <cylinder length="0.05" radius="0.1"/>
        </geometry>
      </collision>
      
      <visual name="back_left_wheel_visual">
        <origin rpy="0 1.5707 1.5707" xyz="-0.175 0.25 0.1"/>
        <geometry>
          <cylinder length="0.05" radius="0.1"/>
        </geometry>  
        <material name="Black"/>    
      </visual>      
 </link>

  <!-- ________________FRONT RIGHT WHEEL LINK________________   -->
  <link name="front_left_wheel">    
    <inertial>
      <origin rpy="0 0 0 " xyz="0 0 0"/>
      <mass value="5"/>
      <inertia ixx="0.1" ixy="0" ixz="0" iyy="0.1" iyz="0" izz="0.1"/>
    </inertial>
    
    <collision name="front_left_wheel_collision">
      <origin rpy="0 1.5707 1.5707" xyz="0 0 0" />
      <geometry>
        <cylinder length="0.05" radius="0.1"/>
      </geometry>
    </collision>
    
    <visual name="front_left_wheel_visual">
      <origin rpy="0 1.5707 1.5707" xyz="0 0 0"/>
      <geometry>
        <cylinder length="0.05" radius="0.1"/>
      </geometry>
      <material name="Black"/>      
    </visual>
    
  </link>
  <joint name="joint_front_left_wheel" type="continuous">
    <origin rpy="0 0 0" xyz="0.175 0.25 0.1"/>
    <child link="front_left_wheel" />
    <parent link="chassis"/>
    <axis rpy="0 0 0" xyz="0 1 0"/>
  </joint>  

  <!--________________ FRONT LEFTT WHEEL LINK________________ -->
  <link name="front_right_wheel">    
    <inertial>
      <mass value="5"/>
      <origin rpy="0 0 0" xyz="0 0 0"/>
      <inertia ixx="0.1" ixy="0" ixz="0" iyy="0.1" iyz="0" izz="0.1"/>
    </inertial>
    
    <collision name="front_right_wheel_collision">
      <origin rpy="0 1.5707 1.5707" xyz="0 0 0" />
      <geometry>
        <cylinder length="0.05" radius="0.1"/>
      </geometry>
    </collision>
    
    <visual name="front_right_wheel_visual">
      <origin rpy="0 1.5707 1.5707" xyz="0 0 0"/>
      <geometry>
        <cylinder length="0.05" radius="0.1"/>
      </geometry>   
      <material name="Black"/>   
    </visual>
    
  </link>
  <joint name="joint_front_right_wheel" type="continuous">
    <origin rpy="0 0 0" xyz="0.175 -0.25 0.1"/>
    <child link="front_right_wheel" />
    <parent link="chassis"/>
    <axis rpy="0 0 0" xyz="0 1 0"/>
  </joint>   

  <!--________________ LIDAR LINK________________ --> 
  <link name="lidar">
    <inertial>
       <origin xyz="0.0 0.0 0.0" rpy="0.0 0.0 0.0"/>
      <mass value=".10"/>
      <inertia ixx="1.0" ixy="0.0" ixz="0.0" iyy="1.0" iyz="0.0" izz="1.0"/>
    </inertial>
    <visual>
      <origin xyz=" 0 0 0" rpy="0 0 0"/>
      <geometry>
     <mesh filename="package://description_pkg/meshes/lidar.STL" />     
      </geometry>
      <material name="Blue"/>
    </visual>
    <collision>
      <origin xyz="0.0 0.0 0.0" rpy="0.0 0.0 0.0"/>
      <geometry>
        <mesh filename="package://description_pkg/meshes/lidar.STL" />
       </geometry>  
    </collision>
    </link>
    <joint name="lider_joint" type="fixed">
        <origin xyz="0.220 0.0 0.305" rpy="0 0 0"/>
        <parent link="chassis"/>
        <child link="lidar"/>
        <axis xyz="0 0 0" />
    </joint>
   
  <gazebo>
   <plugin name="differential_drive_controller" filename="libgazebo_ros_diff_drive.so">
       <updateRate>30.0</updateRate>
      <commandTopic>cmd_vel</commandTopic>
      <odometryTopic>odom</odometryTopic>
      <odometryFrame>odom</odometryFrame>
      <odometrySource>world</odometrySource>
      <publishOdomTF>true</publishOdomTF>
      <robotBaseFrame>base_link</robotBaseFrame>
      <publishWheelTF>false</publishWheelTF>
      <publishTf>true</publishTf>
      <publishWheelJointState>true</publishWheelJointState>
      <legacyMode>false</legacyMode>
      <updateRate>30</updateRate>
      <leftJoint>joint_front_left_wheel</leftJoint>
      <rightJoint>joint_front_right_wheel</rightJoint>
      <wheelSeparation>0.5</wheelSeparation>
      <wheelDiameter>0.2</wheelDiameter>
      <wheelAcceleration>10</wheelAcceleration>
      <wheelTorque>20</wheelTorque>
      <rosDebugLevel>na</rosDebugLevel>
    </plugin>
  </gazebo>

 
  <gazebo reference="chassis">
    <material>Gazebo/White</material>
  </gazebo>  
  <gazebo reference="front_right_wheel">
    <material>Gazebo/White</material>
  </gazebo> 
  <gazebo reference="front_left_wheel">
    <material>Gazebo/White</material>
  </gazebo> 
  <gazebo reference="lidar">
    <material>Gazebo/Black</material>
  </gazebo> 

     <!-- LIDER -->
    <gazebo reference="lidar">
        <sensor type="ray" name="head_hokuyo_sensor">
            <pose>0 0 0 0 0 0</pose>
            <visualize>true</visualize>
            <update_rate>40</update_rate>
            <ray>
                <scan>
                    <horizontal>
                        <samples>360</samples>
                        <resolution>1</resolution>
                        <min_angle>-1.570796327</min_angle>
                        <max_angle>1.570796327</max_angle>
                    </horizontal>
                </scan>
                <range>
                    <min>0.10</min>
                    <max>30.0</max>
                    <resolution>0.01</resolution>
                </range>
                <noise>
                    <type>gaussian</type>
                    <!-- Noise parameters based on published spec for Hokuyo laser
                        achieving "+-30mm" accuracy at range < 10m.  A mean of 0.0m and
                        stddev of 0.01m will put 99.7% of samples within 0.03m of the true
                        reading. -->
                    <mean>0.0</mean>
                    <stddev>0.01</stddev>
                </noise>
            </ray>
            <plugin name="gazebo_ros_head_hokuyo_controller" filename="libgazebo_ros_laser.so">
                <topicName>scan</topicName>
                <frameName>lidar</frameName>
            </plugin>
        </sensor>
    </gazebo>


</robot>


